Traceback (most recent call last):
  File "/Users/kashnitskiyy/opt/anaconda3/envs/mlcourse/lib/python3.8/site-packages/jupyter_cache/executors/utils.py", line 51, in single_nb_execution
    executenb(
  File "/Users/kashnitskiyy/opt/anaconda3/envs/mlcourse/lib/python3.8/site-packages/nbclient/client.py", line 1093, in execute
    return NotebookClient(nb=nb, resources=resources, km=km, **kwargs).execute()
  File "/Users/kashnitskiyy/opt/anaconda3/envs/mlcourse/lib/python3.8/site-packages/nbclient/util.py", line 84, in wrapped
    return just_run(coro(*args, **kwargs))
  File "/Users/kashnitskiyy/opt/anaconda3/envs/mlcourse/lib/python3.8/site-packages/nbclient/util.py", line 62, in just_run
    return loop.run_until_complete(coro)
  File "/Users/kashnitskiyy/opt/anaconda3/envs/mlcourse/lib/python3.8/asyncio/base_events.py", line 616, in run_until_complete
    return future.result()
  File "/Users/kashnitskiyy/opt/anaconda3/envs/mlcourse/lib/python3.8/site-packages/nbclient/client.py", line 559, in async_execute
    await self.async_execute_cell(
  File "/Users/kashnitskiyy/opt/anaconda3/envs/mlcourse/lib/python3.8/site-packages/nbclient/client.py", line 854, in async_execute_cell
    self._check_raise_for_error(cell, exec_reply)
  File "/Users/kashnitskiyy/opt/anaconda3/envs/mlcourse/lib/python3.8/site-packages/nbclient/client.py", line 756, in _check_raise_for_error
    raise CellExecutionError.from_cell_and_msg(cell, exec_reply_content)
nbclient.exceptions.CellExecutionError: An error occurred while executing the following cell:
------------------
# Change site1, ..., site10 columns type to integer and fill NA-values with zeros
sites = ["site%s" % i for i in range(1, 11)]
train_df[sites] = train_df[sites].fillna(0).astype(np.uint16)
test_df[sites] = test_df[sites].fillna(0).astype(np.uint16)

# Load websites dictionary
with open(r"../../data/site_dic.pkl", "rb") as input_file:
    site_dict = pickle.load(input_file)

# Create dataframe for the dictionary
sites_dict = pd.DataFrame(
    list(site_dict.keys()), index=list(site_dict.values()), columns=["site"]
)
print(u"Websites total:", sites_dict.shape[0])
sites_dict.head()
------------------

[0;31m---------------------------------------------------------------------------[0m
[0;31mFileNotFoundError[0m                         Traceback (most recent call last)
[0;32m/var/folders/xs/x4nxtnxd4qq06sg5z0x951q1q7mkqq/T/ipykernel_21184/3701445125.py[0m in [0;36m<module>[0;34m[0m
[1;32m      5[0m [0;34m[0m[0m
[1;32m      6[0m [0;31m# Load websites dictionary[0m[0;34m[0m[0;34m[0m[0;34m[0m[0m
[0;32m----> 7[0;31m [0;32mwith[0m [0mopen[0m[0;34m([0m[0;34mr"../../data/site_dic.pkl"[0m[0;34m,[0m [0;34m"rb"[0m[0;34m)[0m [0;32mas[0m [0minput_file[0m[0;34m:[0m[0;34m[0m[0;34m[0m[0m
[0m[1;32m      8[0m     [0msite_dict[0m [0;34m=[0m [0mpickle[0m[0;34m.[0m[0mload[0m[0;34m([0m[0minput_file[0m[0;34m)[0m[0;34m[0m[0;34m[0m[0m
[1;32m      9[0m [0;34m[0m[0m

[0;31mFileNotFoundError[0m: [Errno 2] No such file or directory: '../../data/site_dic.pkl'
FileNotFoundError: [Errno 2] No such file or directory: '../../data/site_dic.pkl'

